"POST /accounts/login/ HTTP/1.1" 500 59
"POST /accounts/login/ HTTP/1.1" 500 59
"POST /accounts/login/ HTTP/1.1" 500 59
"POST /accounts/login/?next=/clients/ HTTP/1.1" 500 59
"POST /accounts/login/?next=/deal_list/ HTTP/1.1" 500 59
"POST /accounts/login/?next=/clients/ HTTP/1.1" 500 59
"GET /accounts/login/?next=/clients/ HTTP/1.1" 500 59
"GET /accounts/login/?next=/clients/ HTTP/1.1" 500 59
"GET /accounts/login/ HTTP/1.1" 500 59
"GET /signup/ HTTP/1.1" 500 59
"GET /accounts/login/?next=/deal_list/ HTTP/1.1" 500 59
"GET /accounts/login/?next=/deal_list/ HTTP/1.1" 500 59
"GET /accounts/login/?next=/deal_list/ HTTP/1.1" 500 59
Internal Server Error: /accounts/login/
Traceback (most recent call last):
  File "C:\Users\bagda\CRM-system\venv\Lib\site-packages\django\core\handlers\exception.py", line 55, in inner
    response = get_response(request)
  File "C:\Users\bagda\CRM-system\venv\Lib\site-packages\django\core\handlers\base.py", line 220, in _get_response
    response = response.render()
  File "C:\Users\bagda\CRM-system\venv\Lib\site-packages\django\template\response.py", line 114, in render
    self.content = self.rendered_content
                   ^^^^^^^^^^^^^^^^^^^^^
  File "C:\Users\bagda\CRM-system\venv\Lib\site-packages\django\template\response.py", line 90, in rendered_content
    template = self.resolve_template(self.template_name)
  File "C:\Users\bagda\CRM-system\venv\Lib\site-packages\django\template\response.py", line 72, in resolve_template
    return select_template(template, using=self.using)
  File "C:\Users\bagda\CRM-system\venv\Lib\site-packages\django\template\loader.py", line 47, in select_template
    raise TemplateDoesNotExist(", ".join(template_name_list), chain=chain)
django.template.exceptions.TemplateDoesNotExist: registration/login.html
"GET /accounts/login/?next=/deal_list/ HTTP/1.1" 500 82553
Internal Server Error: /accounts/login/
Traceback (most recent call last):
  File "C:\Users\bagda\CRM-system\venv\Lib\site-packages\django\core\handlers\exception.py", line 55, in inner
    response = get_response(request)
  File "C:\Users\bagda\CRM-system\venv\Lib\site-packages\django\core\handlers\base.py", line 220, in _get_response
    response = response.render()
  File "C:\Users\bagda\CRM-system\venv\Lib\site-packages\django\template\response.py", line 114, in render
    self.content = self.rendered_content
                   ^^^^^^^^^^^^^^^^^^^^^
  File "C:\Users\bagda\CRM-system\venv\Lib\site-packages\django\template\response.py", line 90, in rendered_content
    template = self.resolve_template(self.template_name)
  File "C:\Users\bagda\CRM-system\venv\Lib\site-packages\django\template\response.py", line 72, in resolve_template
    return select_template(template, using=self.using)
  File "C:\Users\bagda\CRM-system\venv\Lib\site-packages\django\template\loader.py", line 47, in select_template
    raise TemplateDoesNotExist(", ".join(template_name_list), chain=chain)
django.template.exceptions.TemplateDoesNotExist: registration/login.html
"GET /accounts/login/?next=/deal_list/ HTTP/1.1" 500 82553
Internal Server Error: /accounts/login/
Traceback (most recent call last):
  File "C:\Users\bagda\CRM-system\venv\Lib\site-packages\django\core\handlers\exception.py", line 55, in inner
    response = get_response(request)
  File "C:\Users\bagda\CRM-system\venv\Lib\site-packages\django\core\handlers\base.py", line 220, in _get_response
    response = response.render()
  File "C:\Users\bagda\CRM-system\venv\Lib\site-packages\django\template\response.py", line 114, in render
    self.content = self.rendered_content
                   ^^^^^^^^^^^^^^^^^^^^^
  File "C:\Users\bagda\CRM-system\venv\Lib\site-packages\django\template\response.py", line 90, in rendered_content
    template = self.resolve_template(self.template_name)
  File "C:\Users\bagda\CRM-system\venv\Lib\site-packages\django\template\response.py", line 72, in resolve_template
    return select_template(template, using=self.using)
  File "C:\Users\bagda\CRM-system\venv\Lib\site-packages\django\template\loader.py", line 47, in select_template
    raise TemplateDoesNotExist(", ".join(template_name_list), chain=chain)
django.template.exceptions.TemplateDoesNotExist: registration/login.html
"GET /accounts/login/?next=/deal_list/ HTTP/1.1" 500 82553
Internal Server Error: /accounts/login/
Traceback (most recent call last):
  File "C:\Users\bagda\CRM-system\venv\Lib\site-packages\django\core\handlers\exception.py", line 55, in inner
    response = get_response(request)
  File "C:\Users\bagda\CRM-system\venv\Lib\site-packages\django\core\handlers\base.py", line 220, in _get_response
    response = response.render()
  File "C:\Users\bagda\CRM-system\venv\Lib\site-packages\django\template\response.py", line 114, in render
    self.content = self.rendered_content
                   ^^^^^^^^^^^^^^^^^^^^^
  File "C:\Users\bagda\CRM-system\venv\Lib\site-packages\django\template\response.py", line 90, in rendered_content
    template = self.resolve_template(self.template_name)
  File "C:\Users\bagda\CRM-system\venv\Lib\site-packages\django\template\response.py", line 72, in resolve_template
    return select_template(template, using=self.using)
  File "C:\Users\bagda\CRM-system\venv\Lib\site-packages\django\template\loader.py", line 47, in select_template
    raise TemplateDoesNotExist(", ".join(template_name_list), chain=chain)
django.template.exceptions.TemplateDoesNotExist: registration/login.html
"GET /accounts/login/?next=/deal_list/ HTTP/1.1" 500 82553
Internal Server Error: /accounts/login/
Traceback (most recent call last):
  File "C:\Users\bagda\CRM-system\venv\Lib\site-packages\django\template\backends\django.py", line 107, in render
    return self.template.render(context)
           ~~~~~~~~~~~~~~~~~~~~^^^^^^^^^
  File "C:\Users\bagda\CRM-system\venv\Lib\site-packages\django\template\base.py", line 171, in render
    return self._render(context)
           ~~~~~~~~~~~~^^^^^^^^^
  File "C:\Users\bagda\CRM-system\venv\Lib\site-packages\django\template\base.py", line 163, in _render
    return self.nodelist.render(context)
           ~~~~~~~~~~~~~~~~~~~~^^^^^^^^^
  File "C:\Users\bagda\CRM-system\venv\Lib\site-packages\django\template\base.py", line 1016, in render
    return SafeString("".join([node.render_annotated(context) for node in self]))
                               ~~~~~~~~~~~~~~~~~~~~~^^^^^^^^^
  File "C:\Users\bagda\CRM-system\venv\Lib\site-packages\django\template\base.py", line 977, in render_annotated
    return self.render(context)
           ~~~~~~~~~~~^^^^^^^^^
  File "C:\Users\bagda\CRM-system\venv\Lib\site-packages\django\template\loader_tags.py", line 134, in render
    compiled_parent = self.get_parent(context)
  File "C:\Users\bagda\CRM-system\venv\Lib\site-packages\django\template\loader_tags.py", line 131, in get_parent
    return self.find_template(parent, context)
           ~~~~~~~~~~~~~~~~~~^^^^^^^^^^^^^^^^^
  File "C:\Users\bagda\CRM-system\venv\Lib\site-packages\django\template\loader_tags.py", line 109, in find_template
    template, origin = context.template.engine.find_template(
                       ~~~~~~~~~~~~~~~~~~~~~~~~~~~~~~~~~~~~~^
        template_name,
        ^^^^^^^^^^^^^^
        skip=history,
        ^^^^^^^^^^^^^
    )
    ^
  File "C:\Users\bagda\CRM-system\venv\Lib\site-packages\django\template\engine.py", line 163, in find_template
    raise TemplateDoesNotExist(name, tried=tried)
django.template.exceptions.TemplateDoesNotExist: base.html

The above exception was the direct cause of the following exception:

Traceback (most recent call last):
  File "C:\Users\bagda\CRM-system\venv\Lib\site-packages\django\core\handlers\exception.py", line 55, in inner
    response = get_response(request)
  File "C:\Users\bagda\CRM-system\venv\Lib\site-packages\django\core\handlers\base.py", line 220, in _get_response
    response = response.render()
  File "C:\Users\bagda\CRM-system\venv\Lib\site-packages\django\template\response.py", line 114, in render
    self.content = self.rendered_content
                   ^^^^^^^^^^^^^^^^^^^^^
  File "C:\Users\bagda\CRM-system\venv\Lib\site-packages\django\template\response.py", line 92, in rendered_content
    return template.render(context, self._request)
           ~~~~~~~~~~~~~~~^^^^^^^^^^^^^^^^^^^^^^^^
  File "C:\Users\bagda\CRM-system\venv\Lib\site-packages\django\template\backends\django.py", line 109, in render
    reraise(exc, self.backend)
    ~~~~~~~^^^^^^^^^^^^^^^^^^^
  File "C:\Users\bagda\CRM-system\venv\Lib\site-packages\django\template\backends\django.py", line 130, in reraise
    raise new from exc
django.template.exceptions.TemplateDoesNotExist: base.html
"GET /accounts/login/?next=/deal_list/ HTTP/1.1" 500 127615
Internal Server Error: /accounts/login/
Traceback (most recent call last):
  File "C:\Users\bagda\CRM-system\venv\Lib\site-packages\django\template\backends\django.py", line 107, in render
    return self.template.render(context)
           ~~~~~~~~~~~~~~~~~~~~^^^^^^^^^
  File "C:\Users\bagda\CRM-system\venv\Lib\site-packages\django\template\base.py", line 171, in render
    return self._render(context)
           ~~~~~~~~~~~~^^^^^^^^^
  File "C:\Users\bagda\CRM-system\venv\Lib\site-packages\django\template\base.py", line 163, in _render
    return self.nodelist.render(context)
           ~~~~~~~~~~~~~~~~~~~~^^^^^^^^^
  File "C:\Users\bagda\CRM-system\venv\Lib\site-packages\django\template\base.py", line 1016, in render
    return SafeString("".join([node.render_annotated(context) for node in self]))
                               ~~~~~~~~~~~~~~~~~~~~~^^^^^^^^^
  File "C:\Users\bagda\CRM-system\venv\Lib\site-packages\django\template\base.py", line 977, in render_annotated
    return self.render(context)
           ~~~~~~~~~~~^^^^^^^^^
  File "C:\Users\bagda\CRM-system\venv\Lib\site-packages\django\template\loader_tags.py", line 134, in render
    compiled_parent = self.get_parent(context)
  File "C:\Users\bagda\CRM-system\venv\Lib\site-packages\django\template\loader_tags.py", line 131, in get_parent
    return self.find_template(parent, context)
           ~~~~~~~~~~~~~~~~~~^^^^^^^^^^^^^^^^^
  File "C:\Users\bagda\CRM-system\venv\Lib\site-packages\django\template\loader_tags.py", line 109, in find_template
    template, origin = context.template.engine.find_template(
                       ~~~~~~~~~~~~~~~~~~~~~~~~~~~~~~~~~~~~~^
        template_name,
        ^^^^^^^^^^^^^^
        skip=history,
        ^^^^^^^^^^^^^
    )
    ^
  File "C:\Users\bagda\CRM-system\venv\Lib\site-packages\django\template\engine.py", line 163, in find_template
    raise TemplateDoesNotExist(name, tried=tried)
django.template.exceptions.TemplateDoesNotExist: base.html

The above exception was the direct cause of the following exception:

Traceback (most recent call last):
  File "C:\Users\bagda\CRM-system\venv\Lib\site-packages\django\core\handlers\exception.py", line 55, in inner
    response = get_response(request)
  File "C:\Users\bagda\CRM-system\venv\Lib\site-packages\django\core\handlers\base.py", line 220, in _get_response
    response = response.render()
  File "C:\Users\bagda\CRM-system\venv\Lib\site-packages\django\template\response.py", line 114, in render
    self.content = self.rendered_content
                   ^^^^^^^^^^^^^^^^^^^^^
  File "C:\Users\bagda\CRM-system\venv\Lib\site-packages\django\template\response.py", line 92, in rendered_content
    return template.render(context, self._request)
           ~~~~~~~~~~~~~~~^^^^^^^^^^^^^^^^^^^^^^^^
  File "C:\Users\bagda\CRM-system\venv\Lib\site-packages\django\template\backends\django.py", line 109, in render
    reraise(exc, self.backend)
    ~~~~~~~^^^^^^^^^^^^^^^^^^^
  File "C:\Users\bagda\CRM-system\venv\Lib\site-packages\django\template\backends\django.py", line 130, in reraise
    raise new from exc
django.template.exceptions.TemplateDoesNotExist: base.html
"GET /accounts/login/?next=/deal_list/ HTTP/1.1" 500 127615
Internal Server Error: /accounts/login/
Traceback (most recent call last):
  File "C:\Users\bagda\CRM-system\venv\Lib\site-packages\django\template\backends\django.py", line 107, in render
    return self.template.render(context)
           ~~~~~~~~~~~~~~~~~~~~^^^^^^^^^
  File "C:\Users\bagda\CRM-system\venv\Lib\site-packages\django\template\base.py", line 171, in render
    return self._render(context)
           ~~~~~~~~~~~~^^^^^^^^^
  File "C:\Users\bagda\CRM-system\venv\Lib\site-packages\django\template\base.py", line 163, in _render
    return self.nodelist.render(context)
           ~~~~~~~~~~~~~~~~~~~~^^^^^^^^^
  File "C:\Users\bagda\CRM-system\venv\Lib\site-packages\django\template\base.py", line 1016, in render
    return SafeString("".join([node.render_annotated(context) for node in self]))
                               ~~~~~~~~~~~~~~~~~~~~~^^^^^^^^^
  File "C:\Users\bagda\CRM-system\venv\Lib\site-packages\django\template\base.py", line 977, in render_annotated
    return self.render(context)
           ~~~~~~~~~~~^^^^^^^^^
  File "C:\Users\bagda\CRM-system\venv\Lib\site-packages\django\template\loader_tags.py", line 134, in render
    compiled_parent = self.get_parent(context)
  File "C:\Users\bagda\CRM-system\venv\Lib\site-packages\django\template\loader_tags.py", line 131, in get_parent
    return self.find_template(parent, context)
           ~~~~~~~~~~~~~~~~~~^^^^^^^^^^^^^^^^^
  File "C:\Users\bagda\CRM-system\venv\Lib\site-packages\django\template\loader_tags.py", line 109, in find_template
    template, origin = context.template.engine.find_template(
                       ~~~~~~~~~~~~~~~~~~~~~~~~~~~~~~~~~~~~~^
        template_name,
        ^^^^^^^^^^^^^^
        skip=history,
        ^^^^^^^^^^^^^
    )
    ^
  File "C:\Users\bagda\CRM-system\venv\Lib\site-packages\django\template\engine.py", line 163, in find_template
    raise TemplateDoesNotExist(name, tried=tried)
django.template.exceptions.TemplateDoesNotExist: base.html

The above exception was the direct cause of the following exception:

Traceback (most recent call last):
  File "C:\Users\bagda\CRM-system\venv\Lib\site-packages\django\core\handlers\exception.py", line 55, in inner
    response = get_response(request)
  File "C:\Users\bagda\CRM-system\venv\Lib\site-packages\django\core\handlers\base.py", line 220, in _get_response
    response = response.render()
  File "C:\Users\bagda\CRM-system\venv\Lib\site-packages\django\template\response.py", line 114, in render
    self.content = self.rendered_content
                   ^^^^^^^^^^^^^^^^^^^^^
  File "C:\Users\bagda\CRM-system\venv\Lib\site-packages\django\template\response.py", line 92, in rendered_content
    return template.render(context, self._request)
           ~~~~~~~~~~~~~~~^^^^^^^^^^^^^^^^^^^^^^^^
  File "C:\Users\bagda\CRM-system\venv\Lib\site-packages\django\template\backends\django.py", line 109, in render
    reraise(exc, self.backend)
    ~~~~~~~^^^^^^^^^^^^^^^^^^^
  File "C:\Users\bagda\CRM-system\venv\Lib\site-packages\django\template\backends\django.py", line 130, in reraise
    raise new from exc
django.template.exceptions.TemplateDoesNotExist: base.html
"GET /accounts/login/?next=/deal_list/ HTTP/1.1" 500 127615
Internal Server Error: /accounts/login/
Traceback (most recent call last):
  File "C:\Users\bagda\CRM-system\venv\Lib\site-packages\django\template\backends\django.py", line 107, in render
    return self.template.render(context)
           ~~~~~~~~~~~~~~~~~~~~^^^^^^^^^
  File "C:\Users\bagda\CRM-system\venv\Lib\site-packages\django\template\base.py", line 171, in render
    return self._render(context)
           ~~~~~~~~~~~~^^^^^^^^^
  File "C:\Users\bagda\CRM-system\venv\Lib\site-packages\django\template\base.py", line 163, in _render
    return self.nodelist.render(context)
           ~~~~~~~~~~~~~~~~~~~~^^^^^^^^^
  File "C:\Users\bagda\CRM-system\venv\Lib\site-packages\django\template\base.py", line 1016, in render
    return SafeString("".join([node.render_annotated(context) for node in self]))
                               ~~~~~~~~~~~~~~~~~~~~~^^^^^^^^^
  File "C:\Users\bagda\CRM-system\venv\Lib\site-packages\django\template\base.py", line 977, in render_annotated
    return self.render(context)
           ~~~~~~~~~~~^^^^^^^^^
  File "C:\Users\bagda\CRM-system\venv\Lib\site-packages\django\template\loader_tags.py", line 134, in render
    compiled_parent = self.get_parent(context)
  File "C:\Users\bagda\CRM-system\venv\Lib\site-packages\django\template\loader_tags.py", line 131, in get_parent
    return self.find_template(parent, context)
           ~~~~~~~~~~~~~~~~~~^^^^^^^^^^^^^^^^^
  File "C:\Users\bagda\CRM-system\venv\Lib\site-packages\django\template\loader_tags.py", line 109, in find_template
    template, origin = context.template.engine.find_template(
                       ~~~~~~~~~~~~~~~~~~~~~~~~~~~~~~~~~~~~~^
        template_name,
        ^^^^^^^^^^^^^^
        skip=history,
        ^^^^^^^^^^^^^
    )
    ^
  File "C:\Users\bagda\CRM-system\venv\Lib\site-packages\django\template\engine.py", line 163, in find_template
    raise TemplateDoesNotExist(name, tried=tried)
django.template.exceptions.TemplateDoesNotExist: base.html

The above exception was the direct cause of the following exception:

Traceback (most recent call last):
  File "C:\Users\bagda\CRM-system\venv\Lib\site-packages\django\core\handlers\exception.py", line 55, in inner
    response = get_response(request)
  File "C:\Users\bagda\CRM-system\venv\Lib\site-packages\django\core\handlers\base.py", line 220, in _get_response
    response = response.render()
  File "C:\Users\bagda\CRM-system\venv\Lib\site-packages\django\template\response.py", line 114, in render
    self.content = self.rendered_content
                   ^^^^^^^^^^^^^^^^^^^^^
  File "C:\Users\bagda\CRM-system\venv\Lib\site-packages\django\template\response.py", line 92, in rendered_content
    return template.render(context, self._request)
           ~~~~~~~~~~~~~~~^^^^^^^^^^^^^^^^^^^^^^^^
  File "C:\Users\bagda\CRM-system\venv\Lib\site-packages\django\template\backends\django.py", line 109, in render
    reraise(exc, self.backend)
    ~~~~~~~^^^^^^^^^^^^^^^^^^^
  File "C:\Users\bagda\CRM-system\venv\Lib\site-packages\django\template\backends\django.py", line 130, in reraise
    raise new from exc
django.template.exceptions.TemplateDoesNotExist: base.html
"GET /accounts/login/?next=/deal_list/ HTTP/1.1" 500 127615
Internal Server Error: /accounts/login/
Traceback (most recent call last):
  File "C:\Users\bagda\CRM-system\venv\Lib\site-packages\django\db\backends\utils.py", line 105, in _execute
    return self.cursor.execute(sql, params)
           ~~~~~~~~~~~~~~~~~~~^^^^^^^^^^^^^
  File "C:\Users\bagda\CRM-system\venv\Lib\site-packages\django\db\backends\sqlite3\base.py", line 360, in execute
    return super().execute(query, params)
           ~~~~~~~~~~~~~~~^^^^^^^^^^^^^^^
sqlite3.OperationalError: no such table: crm_customuser

The above exception was the direct cause of the following exception:

Traceback (most recent call last):
  File "C:\Users\bagda\CRM-system\venv\Lib\site-packages\django\core\handlers\exception.py", line 55, in inner
    response = get_response(request)
  File "C:\Users\bagda\CRM-system\venv\Lib\site-packages\django\core\handlers\base.py", line 197, in _get_response
    response = wrapped_callback(request, *callback_args, **callback_kwargs)
  File "C:\Users\bagda\CRM-system\venv\Lib\site-packages\django\views\generic\base.py", line 104, in view
    return self.dispatch(request, *args, **kwargs)
           ~~~~~~~~~~~~~^^^^^^^^^^^^^^^^^^^^^^^^^^
  File "C:\Users\bagda\CRM-system\venv\Lib\site-packages\django\utils\decorators.py", line 48, in _wrapper
    return bound_method(*args, **kwargs)
  File "C:\Users\bagda\CRM-system\venv\Lib\site-packages\django\utils\decorators.py", line 48, in _wrapper
    return bound_method(*args, **kwargs)
  File "C:\Users\bagda\CRM-system\venv\Lib\site-packages\django\views\decorators\debug.py", line 143, in sensitive_post_parameters_wrapper
    return view(request, *args, **kwargs)
  File "C:\Users\bagda\CRM-system\venv\Lib\site-packages\django\utils\decorators.py", line 48, in _wrapper
    return bound_method(*args, **kwargs)
  File "C:\Users\bagda\CRM-system\venv\Lib\site-packages\django\utils\decorators.py", line 192, in _view_wrapper
    result = _process_exception(request, e)
  File "C:\Users\bagda\CRM-system\venv\Lib\site-packages\django\utils\decorators.py", line 190, in _view_wrapper
    response = view_func(request, *args, **kwargs)
  File "C:\Users\bagda\CRM-system\venv\Lib\site-packages\django\utils\decorators.py", line 48, in _wrapper
    return bound_method(*args, **kwargs)
  File "C:\Users\bagda\CRM-system\venv\Lib\site-packages\django\views\decorators\cache.py", line 80, in _view_wrapper
    response = view_func(request, *args, **kwargs)
  File "C:\Users\bagda\CRM-system\venv\Lib\site-packages\django\contrib\auth\views.py", line 89, in dispatch
    return super().dispatch(request, *args, **kwargs)
           ~~~~~~~~~~~~~~~~^^^^^^^^^^^^^^^^^^^^^^^^^^
  File "C:\Users\bagda\CRM-system\venv\Lib\site-packages\django\views\generic\base.py", line 143, in dispatch
    return handler(request, *args, **kwargs)
  File "C:\Users\bagda\CRM-system\venv\Lib\site-packages\django\views\generic\edit.py", line 150, in post
    if form.is_valid():
       ~~~~~~~~~~~~~^^
  File "C:\Users\bagda\CRM-system\venv\Lib\site-packages\django\forms\forms.py", line 206, in is_valid
    return self.is_bound and not self.errors
                                 ^^^^^^^^^^^
  File "C:\Users\bagda\CRM-system\venv\Lib\site-packages\django\forms\forms.py", line 201, in errors
    self.full_clean()
    ~~~~~~~~~~~~~~~^^
  File "C:\Users\bagda\CRM-system\venv\Lib\site-packages\django\forms\forms.py", line 338, in full_clean
    self._clean_form()
    ~~~~~~~~~~~~~~~~^^
  File "C:\Users\bagda\CRM-system\venv\Lib\site-packages\django\forms\forms.py", line 354, in _clean_form
    cleaned_data = self.clean()
  File "C:\Users\bagda\CRM-system\venv\Lib\site-packages\django\views\decorators\debug.py", line 75, in sensitive_variables_wrapper
    return func(*func_args, **func_kwargs)
  File "C:\Users\bagda\CRM-system\venv\Lib\site-packages\django\contrib\auth\forms.py", line 366, in clean
    self.user_cache = authenticate(
                      ~~~~~~~~~~~~^
        self.request, username=username, password=password
        ^^^^^^^^^^^^^^^^^^^^^^^^^^^^^^^^^^^^^^^^^^^^^^^^^^
    )
    ^
  File "C:\Users\bagda\CRM-system\venv\Lib\site-packages\django\views\decorators\debug.py", line 75, in sensitive_variables_wrapper
    return func(*func_args, **func_kwargs)
  File "C:\Users\bagda\CRM-system\venv\Lib\site-packages\django\contrib\auth\__init__.py", line 114, in authenticate
    user = backend.authenticate(request, **credentials)
  File "C:\Users\bagda\CRM-system\venv\Lib\site-packages\django\contrib\auth\backends.py", line 65, in authenticate
    user = UserModel._default_manager.get_by_natural_key(username)
  File "C:\Users\bagda\CRM-system\venv\Lib\site-packages\django\contrib\auth\base_user.py", line 37, in get_by_natural_key
    return self.get(**{self.model.USERNAME_FIELD: username})
           ~~~~~~~~^^^^^^^^^^^^^^^^^^^^^^^^^^^^^^^^^^^^^^^^^
  File "C:\Users\bagda\CRM-system\venv\Lib\site-packages\django\db\models\manager.py", line 87, in manager_method
    return getattr(self.get_queryset(), name)(*args, **kwargs)
           ~~~~~~~~~~~~~~~~~~~~~~~~~~~~~~~~~~^^^^^^^^^^^^^^^^^
  File "C:\Users\bagda\CRM-system\venv\Lib\site-packages\django\db\models\query.py", line 629, in get
    num = len(clone)
  File "C:\Users\bagda\CRM-system\venv\Lib\site-packages\django\db\models\query.py", line 366, in __len__
    self._fetch_all()
    ~~~~~~~~~~~~~~~^^
  File "C:\Users\bagda\CRM-system\venv\Lib\site-packages\django\db\models\query.py", line 1935, in _fetch_all
    self._result_cache = list(self._iterable_class(self))
                         ~~~~^^^^^^^^^^^^^^^^^^^^^^^^^^^^
  File "C:\Users\bagda\CRM-system\venv\Lib\site-packages\django\db\models\query.py", line 91, in __iter__
    results = compiler.execute_sql(
        chunked_fetch=self.chunked_fetch, chunk_size=self.chunk_size
    )
  File "C:\Users\bagda\CRM-system\venv\Lib\site-packages\django\db\models\sql\compiler.py", line 1622, in execute_sql
    cursor.execute(sql, params)
    ~~~~~~~~~~~~~~^^^^^^^^^^^^^
  File "C:\Users\bagda\CRM-system\venv\Lib\site-packages\django\db\backends\utils.py", line 122, in execute
    return super().execute(sql, params)
           ~~~~~~~~~~~~~~~^^^^^^^^^^^^^
  File "C:\Users\bagda\CRM-system\venv\Lib\site-packages\django\db\backends\utils.py", line 79, in execute
    return self._execute_with_wrappers(
           ~~~~~~~~~~~~~~~~~~~~~~~~~~~^
        sql, params, many=False, executor=self._execute
        ^^^^^^^^^^^^^^^^^^^^^^^^^^^^^^^^^^^^^^^^^^^^^^^
    )
    ^
  File "C:\Users\bagda\CRM-system\venv\Lib\site-packages\django\db\backends\utils.py", line 92, in _execute_with_wrappers
    return executor(sql, params, many, context)
  File "C:\Users\bagda\CRM-system\venv\Lib\site-packages\django\db\backends\utils.py", line 100, in _execute
    with self.db.wrap_database_errors:
         ^^^^^^^^^^^^^^^^^^^^^^^^^^^^
  File "C:\Users\bagda\CRM-system\venv\Lib\site-packages\django\db\utils.py", line 91, in __exit__
    raise dj_exc_value.with_traceback(traceback) from exc_value
  File "C:\Users\bagda\CRM-system\venv\Lib\site-packages\django\db\backends\utils.py", line 105, in _execute
    return self.cursor.execute(sql, params)
           ~~~~~~~~~~~~~~~~~~~^^^^^^^^^^^^^
  File "C:\Users\bagda\CRM-system\venv\Lib\site-packages\django\db\backends\sqlite3\base.py", line 360, in execute
    return super().execute(query, params)
           ~~~~~~~~~~~~~~~^^^^^^^^^^^^^^^
django.db.utils.OperationalError: no such table: crm_customuser
"POST /accounts/login/?next=/deal_list/ HTTP/1.1" 500 239644
Internal Server Error: /login/
Traceback (most recent call last):
  File "C:\Users\bagda\CRM-system\venv\Lib\site-packages\django\db\backends\utils.py", line 105, in _execute
    return self.cursor.execute(sql, params)
           ~~~~~~~~~~~~~~~~~~~^^^^^^^^^^^^^
  File "C:\Users\bagda\CRM-system\venv\Lib\site-packages\django\db\backends\sqlite3\base.py", line 360, in execute
    return super().execute(query, params)
           ~~~~~~~~~~~~~~~^^^^^^^^^^^^^^^
sqlite3.OperationalError: no such table: crm_customuser

The above exception was the direct cause of the following exception:

Traceback (most recent call last):
  File "C:\Users\bagda\CRM-system\venv\Lib\site-packages\django\core\handlers\exception.py", line 55, in inner
    response = get_response(request)
  File "C:\Users\bagda\CRM-system\venv\Lib\site-packages\django\core\handlers\base.py", line 197, in _get_response
    response = wrapped_callback(request, *callback_args, **callback_kwargs)
  File "C:\Users\bagda\CRM-system\venv\Lib\site-packages\django\views\generic\base.py", line 104, in view
    return self.dispatch(request, *args, **kwargs)
           ~~~~~~~~~~~~~^^^^^^^^^^^^^^^^^^^^^^^^^^
  File "C:\Users\bagda\CRM-system\venv\Lib\site-packages\django\utils\decorators.py", line 48, in _wrapper
    return bound_method(*args, **kwargs)
  File "C:\Users\bagda\CRM-system\venv\Lib\site-packages\django\utils\decorators.py", line 48, in _wrapper
    return bound_method(*args, **kwargs)
  File "C:\Users\bagda\CRM-system\venv\Lib\site-packages\django\views\decorators\debug.py", line 143, in sensitive_post_parameters_wrapper
    return view(request, *args, **kwargs)
  File "C:\Users\bagda\CRM-system\venv\Lib\site-packages\django\utils\decorators.py", line 48, in _wrapper
    return bound_method(*args, **kwargs)
  File "C:\Users\bagda\CRM-system\venv\Lib\site-packages\django\utils\decorators.py", line 192, in _view_wrapper
    result = _process_exception(request, e)
  File "C:\Users\bagda\CRM-system\venv\Lib\site-packages\django\utils\decorators.py", line 190, in _view_wrapper
    response = view_func(request, *args, **kwargs)
  File "C:\Users\bagda\CRM-system\venv\Lib\site-packages\django\utils\decorators.py", line 48, in _wrapper
    return bound_method(*args, **kwargs)
  File "C:\Users\bagda\CRM-system\venv\Lib\site-packages\django\views\decorators\cache.py", line 80, in _view_wrapper
    response = view_func(request, *args, **kwargs)
  File "C:\Users\bagda\CRM-system\venv\Lib\site-packages\django\contrib\auth\views.py", line 89, in dispatch
    return super().dispatch(request, *args, **kwargs)
           ~~~~~~~~~~~~~~~~^^^^^^^^^^^^^^^^^^^^^^^^^^
  File "C:\Users\bagda\CRM-system\venv\Lib\site-packages\django\views\generic\base.py", line 143, in dispatch
    return handler(request, *args, **kwargs)
  File "C:\Users\bagda\CRM-system\venv\Lib\site-packages\django\views\generic\edit.py", line 150, in post
    if form.is_valid():
       ~~~~~~~~~~~~~^^
  File "C:\Users\bagda\CRM-system\venv\Lib\site-packages\django\forms\forms.py", line 206, in is_valid
    return self.is_bound and not self.errors
                                 ^^^^^^^^^^^
  File "C:\Users\bagda\CRM-system\venv\Lib\site-packages\django\forms\forms.py", line 201, in errors
    self.full_clean()
    ~~~~~~~~~~~~~~~^^
  File "C:\Users\bagda\CRM-system\venv\Lib\site-packages\django\forms\forms.py", line 338, in full_clean
    self._clean_form()
    ~~~~~~~~~~~~~~~~^^
  File "C:\Users\bagda\CRM-system\venv\Lib\site-packages\django\forms\forms.py", line 354, in _clean_form
    cleaned_data = self.clean()
  File "C:\Users\bagda\CRM-system\venv\Lib\site-packages\django\views\decorators\debug.py", line 75, in sensitive_variables_wrapper
    return func(*func_args, **func_kwargs)
  File "C:\Users\bagda\CRM-system\venv\Lib\site-packages\django\contrib\auth\forms.py", line 366, in clean
    self.user_cache = authenticate(
                      ~~~~~~~~~~~~^
        self.request, username=username, password=password
        ^^^^^^^^^^^^^^^^^^^^^^^^^^^^^^^^^^^^^^^^^^^^^^^^^^
    )
    ^
  File "C:\Users\bagda\CRM-system\venv\Lib\site-packages\django\views\decorators\debug.py", line 75, in sensitive_variables_wrapper
    return func(*func_args, **func_kwargs)
  File "C:\Users\bagda\CRM-system\venv\Lib\site-packages\django\contrib\auth\__init__.py", line 114, in authenticate
    user = backend.authenticate(request, **credentials)
  File "C:\Users\bagda\CRM-system\venv\Lib\site-packages\django\contrib\auth\backends.py", line 65, in authenticate
    user = UserModel._default_manager.get_by_natural_key(username)
  File "C:\Users\bagda\CRM-system\venv\Lib\site-packages\django\contrib\auth\base_user.py", line 37, in get_by_natural_key
    return self.get(**{self.model.USERNAME_FIELD: username})
           ~~~~~~~~^^^^^^^^^^^^^^^^^^^^^^^^^^^^^^^^^^^^^^^^^
  File "C:\Users\bagda\CRM-system\venv\Lib\site-packages\django\db\models\manager.py", line 87, in manager_method
    return getattr(self.get_queryset(), name)(*args, **kwargs)
           ~~~~~~~~~~~~~~~~~~~~~~~~~~~~~~~~~~^^^^^^^^^^^^^^^^^
  File "C:\Users\bagda\CRM-system\venv\Lib\site-packages\django\db\models\query.py", line 629, in get
    num = len(clone)
  File "C:\Users\bagda\CRM-system\venv\Lib\site-packages\django\db\models\query.py", line 366, in __len__
    self._fetch_all()
    ~~~~~~~~~~~~~~~^^
  File "C:\Users\bagda\CRM-system\venv\Lib\site-packages\django\db\models\query.py", line 1935, in _fetch_all
    self._result_cache = list(self._iterable_class(self))
                         ~~~~^^^^^^^^^^^^^^^^^^^^^^^^^^^^
  File "C:\Users\bagda\CRM-system\venv\Lib\site-packages\django\db\models\query.py", line 91, in __iter__
    results = compiler.execute_sql(
        chunked_fetch=self.chunked_fetch, chunk_size=self.chunk_size
    )
  File "C:\Users\bagda\CRM-system\venv\Lib\site-packages\django\db\models\sql\compiler.py", line 1622, in execute_sql
    cursor.execute(sql, params)
    ~~~~~~~~~~~~~~^^^^^^^^^^^^^
  File "C:\Users\bagda\CRM-system\venv\Lib\site-packages\django\db\backends\utils.py", line 122, in execute
    return super().execute(sql, params)
           ~~~~~~~~~~~~~~~^^^^^^^^^^^^^
  File "C:\Users\bagda\CRM-system\venv\Lib\site-packages\django\db\backends\utils.py", line 79, in execute
    return self._execute_with_wrappers(
           ~~~~~~~~~~~~~~~~~~~~~~~~~~~^
        sql, params, many=False, executor=self._execute
        ^^^^^^^^^^^^^^^^^^^^^^^^^^^^^^^^^^^^^^^^^^^^^^^
    )
    ^
  File "C:\Users\bagda\CRM-system\venv\Lib\site-packages\django\db\backends\utils.py", line 92, in _execute_with_wrappers
    return executor(sql, params, many, context)
  File "C:\Users\bagda\CRM-system\venv\Lib\site-packages\django\db\backends\utils.py", line 100, in _execute
    with self.db.wrap_database_errors:
         ^^^^^^^^^^^^^^^^^^^^^^^^^^^^
  File "C:\Users\bagda\CRM-system\venv\Lib\site-packages\django\db\utils.py", line 91, in __exit__
    raise dj_exc_value.with_traceback(traceback) from exc_value
  File "C:\Users\bagda\CRM-system\venv\Lib\site-packages\django\db\backends\utils.py", line 105, in _execute
    return self.cursor.execute(sql, params)
           ~~~~~~~~~~~~~~~~~~~^^^^^^^^^^^^^
  File "C:\Users\bagda\CRM-system\venv\Lib\site-packages\django\db\backends\sqlite3\base.py", line 360, in execute
    return super().execute(query, params)
           ~~~~~~~~~~~~~~~^^^^^^^^^^^^^^^
django.db.utils.OperationalError: no such table: crm_customuser
"POST /login/?next=/clients/ HTTP/1.1" 500 239386
Internal Server Error: /login/
Traceback (most recent call last):
  File "C:\Users\bagda\CRM-system\venv\Lib\site-packages\django\db\backends\utils.py", line 105, in _execute
    return self.cursor.execute(sql, params)
           ~~~~~~~~~~~~~~~~~~~^^^^^^^^^^^^^
  File "C:\Users\bagda\CRM-system\venv\Lib\site-packages\django\db\backends\sqlite3\base.py", line 360, in execute
    return super().execute(query, params)
           ~~~~~~~~~~~~~~~^^^^^^^^^^^^^^^
sqlite3.OperationalError: no such table: crm_customuser

The above exception was the direct cause of the following exception:

Traceback (most recent call last):
  File "C:\Users\bagda\CRM-system\venv\Lib\site-packages\django\core\handlers\exception.py", line 55, in inner
    response = get_response(request)
  File "C:\Users\bagda\CRM-system\venv\Lib\site-packages\django\core\handlers\base.py", line 197, in _get_response
    response = wrapped_callback(request, *callback_args, **callback_kwargs)
  File "C:\Users\bagda\CRM-system\venv\Lib\site-packages\django\views\generic\base.py", line 104, in view
    return self.dispatch(request, *args, **kwargs)
           ~~~~~~~~~~~~~^^^^^^^^^^^^^^^^^^^^^^^^^^
  File "C:\Users\bagda\CRM-system\venv\Lib\site-packages\django\utils\decorators.py", line 48, in _wrapper
    return bound_method(*args, **kwargs)
  File "C:\Users\bagda\CRM-system\venv\Lib\site-packages\django\utils\decorators.py", line 48, in _wrapper
    return bound_method(*args, **kwargs)
  File "C:\Users\bagda\CRM-system\venv\Lib\site-packages\django\views\decorators\debug.py", line 143, in sensitive_post_parameters_wrapper
    return view(request, *args, **kwargs)
  File "C:\Users\bagda\CRM-system\venv\Lib\site-packages\django\utils\decorators.py", line 48, in _wrapper
    return bound_method(*args, **kwargs)
  File "C:\Users\bagda\CRM-system\venv\Lib\site-packages\django\utils\decorators.py", line 192, in _view_wrapper
    result = _process_exception(request, e)
  File "C:\Users\bagda\CRM-system\venv\Lib\site-packages\django\utils\decorators.py", line 190, in _view_wrapper
    response = view_func(request, *args, **kwargs)
  File "C:\Users\bagda\CRM-system\venv\Lib\site-packages\django\utils\decorators.py", line 48, in _wrapper
    return bound_method(*args, **kwargs)
  File "C:\Users\bagda\CRM-system\venv\Lib\site-packages\django\views\decorators\cache.py", line 80, in _view_wrapper
    response = view_func(request, *args, **kwargs)
  File "C:\Users\bagda\CRM-system\venv\Lib\site-packages\django\contrib\auth\views.py", line 89, in dispatch
    return super().dispatch(request, *args, **kwargs)
           ~~~~~~~~~~~~~~~~^^^^^^^^^^^^^^^^^^^^^^^^^^
  File "C:\Users\bagda\CRM-system\venv\Lib\site-packages\django\views\generic\base.py", line 143, in dispatch
    return handler(request, *args, **kwargs)
  File "C:\Users\bagda\CRM-system\venv\Lib\site-packages\django\views\generic\edit.py", line 150, in post
    if form.is_valid():
       ~~~~~~~~~~~~~^^
  File "C:\Users\bagda\CRM-system\venv\Lib\site-packages\django\forms\forms.py", line 206, in is_valid
    return self.is_bound and not self.errors
                                 ^^^^^^^^^^^
  File "C:\Users\bagda\CRM-system\venv\Lib\site-packages\django\forms\forms.py", line 201, in errors
    self.full_clean()
    ~~~~~~~~~~~~~~~^^
  File "C:\Users\bagda\CRM-system\venv\Lib\site-packages\django\forms\forms.py", line 338, in full_clean
    self._clean_form()
    ~~~~~~~~~~~~~~~~^^
  File "C:\Users\bagda\CRM-system\venv\Lib\site-packages\django\forms\forms.py", line 354, in _clean_form
    cleaned_data = self.clean()
  File "C:\Users\bagda\CRM-system\venv\Lib\site-packages\django\views\decorators\debug.py", line 75, in sensitive_variables_wrapper
    return func(*func_args, **func_kwargs)
  File "C:\Users\bagda\CRM-system\venv\Lib\site-packages\django\contrib\auth\forms.py", line 366, in clean
    self.user_cache = authenticate(
                      ~~~~~~~~~~~~^
        self.request, username=username, password=password
        ^^^^^^^^^^^^^^^^^^^^^^^^^^^^^^^^^^^^^^^^^^^^^^^^^^
    )
    ^
  File "C:\Users\bagda\CRM-system\venv\Lib\site-packages\django\views\decorators\debug.py", line 75, in sensitive_variables_wrapper
    return func(*func_args, **func_kwargs)
  File "C:\Users\bagda\CRM-system\venv\Lib\site-packages\django\contrib\auth\__init__.py", line 114, in authenticate
    user = backend.authenticate(request, **credentials)
  File "C:\Users\bagda\CRM-system\venv\Lib\site-packages\django\contrib\auth\backends.py", line 65, in authenticate
    user = UserModel._default_manager.get_by_natural_key(username)
  File "C:\Users\bagda\CRM-system\venv\Lib\site-packages\django\contrib\auth\base_user.py", line 37, in get_by_natural_key
    return self.get(**{self.model.USERNAME_FIELD: username})
           ~~~~~~~~^^^^^^^^^^^^^^^^^^^^^^^^^^^^^^^^^^^^^^^^^
  File "C:\Users\bagda\CRM-system\venv\Lib\site-packages\django\db\models\manager.py", line 87, in manager_method
    return getattr(self.get_queryset(), name)(*args, **kwargs)
           ~~~~~~~~~~~~~~~~~~~~~~~~~~~~~~~~~~^^^^^^^^^^^^^^^^^
  File "C:\Users\bagda\CRM-system\venv\Lib\site-packages\django\db\models\query.py", line 629, in get
    num = len(clone)
  File "C:\Users\bagda\CRM-system\venv\Lib\site-packages\django\db\models\query.py", line 366, in __len__
    self._fetch_all()
    ~~~~~~~~~~~~~~~^^
  File "C:\Users\bagda\CRM-system\venv\Lib\site-packages\django\db\models\query.py", line 1935, in _fetch_all
    self._result_cache = list(self._iterable_class(self))
                         ~~~~^^^^^^^^^^^^^^^^^^^^^^^^^^^^
  File "C:\Users\bagda\CRM-system\venv\Lib\site-packages\django\db\models\query.py", line 91, in __iter__
    results = compiler.execute_sql(
        chunked_fetch=self.chunked_fetch, chunk_size=self.chunk_size
    )
  File "C:\Users\bagda\CRM-system\venv\Lib\site-packages\django\db\models\sql\compiler.py", line 1622, in execute_sql
    cursor.execute(sql, params)
    ~~~~~~~~~~~~~~^^^^^^^^^^^^^
  File "C:\Users\bagda\CRM-system\venv\Lib\site-packages\django\db\backends\utils.py", line 122, in execute
    return super().execute(sql, params)
           ~~~~~~~~~~~~~~~^^^^^^^^^^^^^
  File "C:\Users\bagda\CRM-system\venv\Lib\site-packages\django\db\backends\utils.py", line 79, in execute
    return self._execute_with_wrappers(
           ~~~~~~~~~~~~~~~~~~~~~~~~~~~^
        sql, params, many=False, executor=self._execute
        ^^^^^^^^^^^^^^^^^^^^^^^^^^^^^^^^^^^^^^^^^^^^^^^
    )
    ^
  File "C:\Users\bagda\CRM-system\venv\Lib\site-packages\django\db\backends\utils.py", line 92, in _execute_with_wrappers
    return executor(sql, params, many, context)
  File "C:\Users\bagda\CRM-system\venv\Lib\site-packages\django\db\backends\utils.py", line 100, in _execute
    with self.db.wrap_database_errors:
         ^^^^^^^^^^^^^^^^^^^^^^^^^^^^
  File "C:\Users\bagda\CRM-system\venv\Lib\site-packages\django\db\utils.py", line 91, in __exit__
    raise dj_exc_value.with_traceback(traceback) from exc_value
  File "C:\Users\bagda\CRM-system\venv\Lib\site-packages\django\db\backends\utils.py", line 105, in _execute
    return self.cursor.execute(sql, params)
           ~~~~~~~~~~~~~~~~~~~^^^^^^^^^^^^^
  File "C:\Users\bagda\CRM-system\venv\Lib\site-packages\django\db\backends\sqlite3\base.py", line 360, in execute
    return super().execute(query, params)
           ~~~~~~~~~~~~~~~^^^^^^^^^^^^^^^
django.db.utils.OperationalError: no such table: crm_customuser
"POST /login/?next=/clients/ HTTP/1.1" 500 239386
Internal Server Error: /accounts/login/
Traceback (most recent call last):
  File "C:\Users\bagda\CRM-system\venv\Lib\site-packages\django\db\backends\utils.py", line 105, in _execute
    return self.cursor.execute(sql, params)
           ~~~~~~~~~~~~~~~~~~~^^^^^^^^^^^^^
  File "C:\Users\bagda\CRM-system\venv\Lib\site-packages\django\db\backends\sqlite3\base.py", line 360, in execute
    return super().execute(query, params)
           ~~~~~~~~~~~~~~~^^^^^^^^^^^^^^^
sqlite3.OperationalError: no such table: crm_customuser

The above exception was the direct cause of the following exception:

Traceback (most recent call last):
  File "C:\Users\bagda\CRM-system\venv\Lib\site-packages\django\core\handlers\exception.py", line 55, in inner
    response = get_response(request)
  File "C:\Users\bagda\CRM-system\venv\Lib\site-packages\django\core\handlers\base.py", line 197, in _get_response
    response = wrapped_callback(request, *callback_args, **callback_kwargs)
  File "C:\Users\bagda\CRM-system\venv\Lib\site-packages\django\views\generic\base.py", line 104, in view
    return self.dispatch(request, *args, **kwargs)
           ~~~~~~~~~~~~~^^^^^^^^^^^^^^^^^^^^^^^^^^
  File "C:\Users\bagda\CRM-system\venv\Lib\site-packages\django\utils\decorators.py", line 48, in _wrapper
    return bound_method(*args, **kwargs)
  File "C:\Users\bagda\CRM-system\venv\Lib\site-packages\django\utils\decorators.py", line 48, in _wrapper
    return bound_method(*args, **kwargs)
  File "C:\Users\bagda\CRM-system\venv\Lib\site-packages\django\views\decorators\debug.py", line 143, in sensitive_post_parameters_wrapper
    return view(request, *args, **kwargs)
  File "C:\Users\bagda\CRM-system\venv\Lib\site-packages\django\utils\decorators.py", line 48, in _wrapper
    return bound_method(*args, **kwargs)
  File "C:\Users\bagda\CRM-system\venv\Lib\site-packages\django\utils\decorators.py", line 192, in _view_wrapper
    result = _process_exception(request, e)
  File "C:\Users\bagda\CRM-system\venv\Lib\site-packages\django\utils\decorators.py", line 190, in _view_wrapper
    response = view_func(request, *args, **kwargs)
  File "C:\Users\bagda\CRM-system\venv\Lib\site-packages\django\utils\decorators.py", line 48, in _wrapper
    return bound_method(*args, **kwargs)
  File "C:\Users\bagda\CRM-system\venv\Lib\site-packages\django\views\decorators\cache.py", line 80, in _view_wrapper
    response = view_func(request, *args, **kwargs)
  File "C:\Users\bagda\CRM-system\venv\Lib\site-packages\django\contrib\auth\views.py", line 89, in dispatch
    return super().dispatch(request, *args, **kwargs)
           ~~~~~~~~~~~~~~~~^^^^^^^^^^^^^^^^^^^^^^^^^^
  File "C:\Users\bagda\CRM-system\venv\Lib\site-packages\django\views\generic\base.py", line 143, in dispatch
    return handler(request, *args, **kwargs)
  File "C:\Users\bagda\CRM-system\venv\Lib\site-packages\django\views\generic\edit.py", line 150, in post
    if form.is_valid():
       ~~~~~~~~~~~~~^^
  File "C:\Users\bagda\CRM-system\venv\Lib\site-packages\django\forms\forms.py", line 206, in is_valid
    return self.is_bound and not self.errors
                                 ^^^^^^^^^^^
  File "C:\Users\bagda\CRM-system\venv\Lib\site-packages\django\forms\forms.py", line 201, in errors
    self.full_clean()
    ~~~~~~~~~~~~~~~^^
  File "C:\Users\bagda\CRM-system\venv\Lib\site-packages\django\forms\forms.py", line 338, in full_clean
    self._clean_form()
    ~~~~~~~~~~~~~~~~^^
  File "C:\Users\bagda\CRM-system\venv\Lib\site-packages\django\forms\forms.py", line 354, in _clean_form
    cleaned_data = self.clean()
  File "C:\Users\bagda\CRM-system\venv\Lib\site-packages\django\views\decorators\debug.py", line 75, in sensitive_variables_wrapper
    return func(*func_args, **func_kwargs)
  File "C:\Users\bagda\CRM-system\venv\Lib\site-packages\django\contrib\auth\forms.py", line 366, in clean
    self.user_cache = authenticate(
                      ~~~~~~~~~~~~^
        self.request, username=username, password=password
        ^^^^^^^^^^^^^^^^^^^^^^^^^^^^^^^^^^^^^^^^^^^^^^^^^^
    )
    ^
  File "C:\Users\bagda\CRM-system\venv\Lib\site-packages\django\views\decorators\debug.py", line 75, in sensitive_variables_wrapper
    return func(*func_args, **func_kwargs)
  File "C:\Users\bagda\CRM-system\venv\Lib\site-packages\django\contrib\auth\__init__.py", line 114, in authenticate
    user = backend.authenticate(request, **credentials)
  File "C:\Users\bagda\CRM-system\venv\Lib\site-packages\django\contrib\auth\backends.py", line 65, in authenticate
    user = UserModel._default_manager.get_by_natural_key(username)
  File "C:\Users\bagda\CRM-system\venv\Lib\site-packages\django\contrib\auth\base_user.py", line 37, in get_by_natural_key
    return self.get(**{self.model.USERNAME_FIELD: username})
           ~~~~~~~~^^^^^^^^^^^^^^^^^^^^^^^^^^^^^^^^^^^^^^^^^
  File "C:\Users\bagda\CRM-system\venv\Lib\site-packages\django\db\models\manager.py", line 87, in manager_method
    return getattr(self.get_queryset(), name)(*args, **kwargs)
           ~~~~~~~~~~~~~~~~~~~~~~~~~~~~~~~~~~^^^^^^^^^^^^^^^^^
  File "C:\Users\bagda\CRM-system\venv\Lib\site-packages\django\db\models\query.py", line 629, in get
    num = len(clone)
  File "C:\Users\bagda\CRM-system\venv\Lib\site-packages\django\db\models\query.py", line 366, in __len__
    self._fetch_all()
    ~~~~~~~~~~~~~~~^^
  File "C:\Users\bagda\CRM-system\venv\Lib\site-packages\django\db\models\query.py", line 1935, in _fetch_all
    self._result_cache = list(self._iterable_class(self))
                         ~~~~^^^^^^^^^^^^^^^^^^^^^^^^^^^^
  File "C:\Users\bagda\CRM-system\venv\Lib\site-packages\django\db\models\query.py", line 91, in __iter__
    results = compiler.execute_sql(
        chunked_fetch=self.chunked_fetch, chunk_size=self.chunk_size
    )
  File "C:\Users\bagda\CRM-system\venv\Lib\site-packages\django\db\models\sql\compiler.py", line 1622, in execute_sql
    cursor.execute(sql, params)
    ~~~~~~~~~~~~~~^^^^^^^^^^^^^
  File "C:\Users\bagda\CRM-system\venv\Lib\site-packages\django\db\backends\utils.py", line 122, in execute
    return super().execute(sql, params)
           ~~~~~~~~~~~~~~~^^^^^^^^^^^^^
  File "C:\Users\bagda\CRM-system\venv\Lib\site-packages\django\db\backends\utils.py", line 79, in execute
    return self._execute_with_wrappers(
           ~~~~~~~~~~~~~~~~~~~~~~~~~~~^
        sql, params, many=False, executor=self._execute
        ^^^^^^^^^^^^^^^^^^^^^^^^^^^^^^^^^^^^^^^^^^^^^^^
    )
    ^
  File "C:\Users\bagda\CRM-system\venv\Lib\site-packages\django\db\backends\utils.py", line 92, in _execute_with_wrappers
    return executor(sql, params, many, context)
  File "C:\Users\bagda\CRM-system\venv\Lib\site-packages\django\db\backends\utils.py", line 100, in _execute
    with self.db.wrap_database_errors:
         ^^^^^^^^^^^^^^^^^^^^^^^^^^^^
  File "C:\Users\bagda\CRM-system\venv\Lib\site-packages\django\db\utils.py", line 91, in __exit__
    raise dj_exc_value.with_traceback(traceback) from exc_value
  File "C:\Users\bagda\CRM-system\venv\Lib\site-packages\django\db\backends\utils.py", line 105, in _execute
    return self.cursor.execute(sql, params)
           ~~~~~~~~~~~~~~~~~~~^^^^^^^^^^^^^
  File "C:\Users\bagda\CRM-system\venv\Lib\site-packages\django\db\backends\sqlite3\base.py", line 360, in execute
    return super().execute(query, params)
           ~~~~~~~~~~~~~~~^^^^^^^^^^^^^^^
django.db.utils.OperationalError: no such table: crm_customuser
"POST /accounts/login/ HTTP/1.1" 500 238985
Internal Server Error: /deal_list/
Traceback (most recent call last):
  File "C:\Users\bagda\CRM-system\venv\Lib\site-packages\django\core\handlers\exception.py", line 55, in inner
    response = get_response(request)
  File "C:\Users\bagda\CRM-system\venv\Lib\site-packages\django\core\handlers\base.py", line 197, in _get_response
    response = wrapped_callback(request, *callback_args, **callback_kwargs)
  File "C:\Users\bagda\CRM-system\venv\Lib\site-packages\django\contrib\auth\decorators.py", line 59, in _view_wrapper
    return view_func(request, *args, **kwargs)
  File "C:\Users\bagda\CRM-system\crm\views.py", line 90, in deal_list
    return render(request, 'crm/deal_list.html', {
        'deals': deals,
        'clients': clients,
        'filters': request.GET
    })
  File "C:\Users\bagda\CRM-system\venv\Lib\site-packages\django\shortcuts.py", line 25, in render
    content = loader.render_to_string(template_name, context, request, using=using)
  File "C:\Users\bagda\CRM-system\venv\Lib\site-packages\django\template\loader.py", line 61, in render_to_string
    template = get_template(template_name, using=using)
  File "C:\Users\bagda\CRM-system\venv\Lib\site-packages\django\template\loader.py", line 15, in get_template
    return engine.get_template(template_name)
           ~~~~~~~~~~~~~~~~~~~^^^^^^^^^^^^^^^
  File "C:\Users\bagda\CRM-system\venv\Lib\site-packages\django\template\backends\django.py", line 79, in get_template
    return Template(self.engine.get_template(template_name), self)
                    ~~~~~~~~~~~~~~~~~~~~~~~~^^^^^^^^^^^^^^^
  File "C:\Users\bagda\CRM-system\venv\Lib\site-packages\django\template\engine.py", line 177, in get_template
    template, origin = self.find_template(template_name)
                       ~~~~~~~~~~~~~~~~~~^^^^^^^^^^^^^^^
  File "C:\Users\bagda\CRM-system\venv\Lib\site-packages\django\template\engine.py", line 159, in find_template
    template = loader.get_template(name, skip=skip)
  File "C:\Users\bagda\CRM-system\venv\Lib\site-packages\django\template\loaders\cached.py", line 57, in get_template
    template = super().get_template(template_name, skip)
  File "C:\Users\bagda\CRM-system\venv\Lib\site-packages\django\template\loaders\base.py", line 28, in get_template
    return Template(
        contents,
    ...<2 lines>...
        self.engine,
    )
  File "C:\Users\bagda\CRM-system\venv\Lib\site-packages\django\template\base.py", line 154, in __init__
    self.nodelist = self.compile_nodelist()
                    ~~~~~~~~~~~~~~~~~~~~~^^
  File "C:\Users\bagda\CRM-system\venv\Lib\site-packages\django\template\base.py", line 196, in compile_nodelist
    nodelist = parser.parse()
  File "C:\Users\bagda\CRM-system\venv\Lib\site-packages\django\template\base.py", line 518, in parse
    raise self.error(token, e)
  File "C:\Users\bagda\CRM-system\venv\Lib\site-packages\django\template\base.py", line 516, in parse
    compiled_result = compile_func(self, token)
  File "C:\Users\bagda\CRM-system\venv\Lib\site-packages\django\template\loader_tags.py", line 299, in do_extends
    nodelist = parser.parse()
  File "C:\Users\bagda\CRM-system\venv\Lib\site-packages\django\template\base.py", line 518, in parse
    raise self.error(token, e)
  File "C:\Users\bagda\CRM-system\venv\Lib\site-packages\django\template\base.py", line 516, in parse
    compiled_result = compile_func(self, token)
  File "C:\Users\bagda\CRM-system\venv\Lib\site-packages\django\template\loader_tags.py", line 299, in do_extends
    nodelist = parser.parse()
  File "C:\Users\bagda\CRM-system\venv\Lib\site-packages\django\template\base.py", line 518, in parse
    raise self.error(token, e)
  File "C:\Users\bagda\CRM-system\venv\Lib\site-packages\django\template\base.py", line 516, in parse
    compiled_result = compile_func(self, token)
  File "C:\Users\bagda\CRM-system\venv\Lib\site-packages\django\template\loader_tags.py", line 228, in do_block
    raise TemplateSyntaxError(
        "'%s' tag with name '%s' appears more than once" % (bits[0], block_name)
    )
django.template.exceptions.TemplateSyntaxError: 'block' tag with name 'content' appears more than once
"GET /deal_list/ HTTP/1.1" 500 217670
Internal Server Error: /signup/
Traceback (most recent call last):
  File "C:\Users\bagda\CRM-system\venv\Lib\site-packages\django\core\handlers\exception.py", line 55, in inner
    response = get_response(request)
  File "C:\Users\bagda\CRM-system\venv\Lib\site-packages\django\core\handlers\base.py", line 197, in _get_response
    response = wrapped_callback(request, *callback_args, **callback_kwargs)
  File "C:\Users\bagda\CRM-system\crm\views.py", line 53, in signup
    form.add_error(None, 'reCAPTCHA validation failed. Please try again.')
    ~~~~~~~~~~~~~~^^^^^^^^^^^^^^^^^^^^^^^^^^^^^^^^^^^^^^^^^^^^^^^^^^^^^^^^
  File "C:\Users\bagda\CRM-system\venv\Lib\site-packages\django\forms\forms.py", line 299, in add_error
    if field not in self.errors:
                    ^^^^^^^^^^^
  File "C:\Users\bagda\CRM-system\venv\Lib\site-packages\django\forms\forms.py", line 201, in errors
    self.full_clean()
    ~~~~~~~~~~~~~~~^^
  File "C:\Users\bagda\CRM-system\venv\Lib\site-packages\django\forms\forms.py", line 337, in full_clean
    self._clean_fields()
    ~~~~~~~~~~~~~~~~~~^^
  File "C:\Users\bagda\CRM-system\venv\Lib\site-packages\django\forms\forms.py", line 347, in _clean_fields
    value = getattr(self, "clean_%s" % name)()
  File "C:\Users\bagda\CRM-system\venv\Lib\site-packages\django\contrib\auth\forms.py", line 277, in clean_username
    and self._meta.model.objects.filter(username__iexact=username).exists()
        ^^^^^^^^^^^^^^^^^^^^^^^^
  File "C:\Users\bagda\CRM-system\venv\Lib\site-packages\django\db\models\manager.py", line 196, in __get__
    raise AttributeError(
    ...<5 lines>...
    )
AttributeError: Manager isn't available; 'auth.User' has been swapped for 'crm.CustomUser'
"POST /signup/ HTTP/1.1" 500 94761
Internal Server Error: /signup/
Traceback (most recent call last):
  File "C:\Users\bagda\CRM-system\venv\Lib\site-packages\django\core\handlers\exception.py", line 55, in inner
    response = get_response(request)
  File "C:\Users\bagda\CRM-system\venv\Lib\site-packages\django\core\handlers\base.py", line 197, in _get_response
    response = wrapped_callback(request, *callback_args, **callback_kwargs)
  File "C:\Users\bagda\CRM-system\crm\views.py", line 57, in signup
    form.add_error(None, 'reCAPTCHA validation failed. Please try again.')
    ~~~~~~~~~~~~~~^^^^^^^^^^^^^^^^^^^^^^^^^^^^^^^^^^^^^^^^^^^^^^^^^^^^^^^^
  File "C:\Users\bagda\CRM-system\venv\Lib\site-packages\django\forms\forms.py", line 299, in add_error
    if field not in self.errors:
                    ^^^^^^^^^^^
  File "C:\Users\bagda\CRM-system\venv\Lib\site-packages\django\forms\forms.py", line 201, in errors
    self.full_clean()
    ~~~~~~~~~~~~~~~^^
  File "C:\Users\bagda\CRM-system\venv\Lib\site-packages\django\forms\forms.py", line 337, in full_clean
    self._clean_fields()
    ~~~~~~~~~~~~~~~~~~^^
  File "C:\Users\bagda\CRM-system\venv\Lib\site-packages\django\forms\forms.py", line 347, in _clean_fields
    value = getattr(self, "clean_%s" % name)()
  File "C:\Users\bagda\CRM-system\venv\Lib\site-packages\django\contrib\auth\forms.py", line 277, in clean_username
    and self._meta.model.objects.filter(username__iexact=username).exists()
        ^^^^^^^^^^^^^^^^^^^^^^^^
  File "C:\Users\bagda\CRM-system\venv\Lib\site-packages\django\db\models\manager.py", line 196, in __get__
    raise AttributeError(
    ...<5 lines>...
    )
AttributeError: Manager isn't available; 'auth.User' has been swapped for 'crm.CustomUser'
"POST /signup/ HTTP/1.1" 500 94761
Internal Server Error: /signup/
Traceback (most recent call last):
  File "C:\Users\bagda\CRM-system\venv\Lib\site-packages\django\core\handlers\exception.py", line 55, in inner
    response = get_response(request)
  File "C:\Users\bagda\CRM-system\venv\Lib\site-packages\django\core\handlers\base.py", line 197, in _get_response
    response = wrapped_callback(request, *callback_args, **callback_kwargs)
  File "C:\Users\bagda\CRM-system\crm\views.py", line 56, in signup
    form.add_error(None, 'reCAPTCHA validation failed. Please try again.')
    ~~~~~~~~~~~~~~^^^^^^^^^^^^^^^^^^^^^^^^^^^^^^^^^^^^^^^^^^^^^^^^^^^^^^^^
  File "C:\Users\bagda\CRM-system\venv\Lib\site-packages\django\forms\forms.py", line 299, in add_error
    if field not in self.errors:
                    ^^^^^^^^^^^
  File "C:\Users\bagda\CRM-system\venv\Lib\site-packages\django\forms\forms.py", line 201, in errors
    self.full_clean()
    ~~~~~~~~~~~~~~~^^
  File "C:\Users\bagda\CRM-system\venv\Lib\site-packages\django\forms\forms.py", line 337, in full_clean
    self._clean_fields()
    ~~~~~~~~~~~~~~~~~~^^
  File "C:\Users\bagda\CRM-system\venv\Lib\site-packages\django\forms\forms.py", line 347, in _clean_fields
    value = getattr(self, "clean_%s" % name)()
  File "C:\Users\bagda\CRM-system\venv\Lib\site-packages\django\contrib\auth\forms.py", line 277, in clean_username
    and self._meta.model.objects.filter(username__iexact=username).exists()
        ^^^^^^^^^^^^^^^^^^^^^^^^
  File "C:\Users\bagda\CRM-system\venv\Lib\site-packages\django\db\models\manager.py", line 196, in __get__
    raise AttributeError(
    ...<5 lines>...
    )
AttributeError: Manager isn't available; 'auth.User' has been swapped for 'crm.CustomUser'
"POST /signup/ HTTP/1.1" 500 94754
Internal Server Error: /deal_list/
Traceback (most recent call last):
  File "C:\Users\bagda\CRM-system\venv\Lib\site-packages\django\core\handlers\exception.py", line 55, in inner
    response = get_response(request)
  File "C:\Users\bagda\CRM-system\venv\Lib\site-packages\django\core\handlers\base.py", line 197, in _get_response
    response = wrapped_callback(request, *callback_args, **callback_kwargs)
  File "C:\Users\bagda\CRM-system\venv\Lib\site-packages\django\contrib\auth\decorators.py", line 59, in _view_wrapper
    return view_func(request, *args, **kwargs)
  File "C:\Users\bagda\CRM-system\crm\views.py", line 129, in deal_list
    return render(request, 'crm/deal_list.html', {
        'deals': deals,
        'clients': clients,
        'filters': request.GET
    })
  File "C:\Users\bagda\CRM-system\venv\Lib\site-packages\django\shortcuts.py", line 25, in render
    content = loader.render_to_string(template_name, context, request, using=using)
  File "C:\Users\bagda\CRM-system\venv\Lib\site-packages\django\template\loader.py", line 61, in render_to_string
    template = get_template(template_name, using=using)
  File "C:\Users\bagda\CRM-system\venv\Lib\site-packages\django\template\loader.py", line 19, in get_template
    raise TemplateDoesNotExist(template_name, chain=chain)
django.template.exceptions.TemplateDoesNotExist: crm/deal_list.html
"GET /deal_list/ HTTP/1.1" 500 90503
Internal Server Error: /deal_list/
Traceback (most recent call last):
  File "C:\Users\bagda\CRM-system\venv\Lib\site-packages\django\core\handlers\exception.py", line 55, in inner
    response = get_response(request)
  File "C:\Users\bagda\CRM-system\venv\Lib\site-packages\django\core\handlers\base.py", line 197, in _get_response
    response = wrapped_callback(request, *callback_args, **callback_kwargs)
  File "C:\Users\bagda\CRM-system\venv\Lib\site-packages\django\contrib\auth\decorators.py", line 59, in _view_wrapper
    return view_func(request, *args, **kwargs)
  File "C:\Users\bagda\CRM-system\crm\views.py", line 129, in deal_list
    return render(request, 'crm/deal_list.html', {
        'deals': deals,
        'clients': clients,
        'filters': request.GET
    })
  File "C:\Users\bagda\CRM-system\venv\Lib\site-packages\django\shortcuts.py", line 25, in render
    content = loader.render_to_string(template_name, context, request, using=using)
  File "C:\Users\bagda\CRM-system\venv\Lib\site-packages\django\template\loader.py", line 61, in render_to_string
    template = get_template(template_name, using=using)
  File "C:\Users\bagda\CRM-system\venv\Lib\site-packages\django\template\loader.py", line 19, in get_template
    raise TemplateDoesNotExist(template_name, chain=chain)
django.template.exceptions.TemplateDoesNotExist: crm/deal_list.html
"GET /deal_list/ HTTP/1.1" 500 90503
